---
title: Try ... Catch ... Finally 문
description: Visual Basic Try/Catch/Finally 문을 사용 하 여 예외 처리를 사용 하는 방법을 알아봅니다.
ms.date: 12/07/2018
f1_keywords:
- vb.Try...Catch...Finally
- vb.when
- vb.Finally
- vb.Catch
- vb.Try
helpviewer_keywords:
- Try...Catch...Finally statements
- Try statement [Visual Basic]
- try-catch exception handling, Try...Catch...Finally statements
- error handling, while running code
- Try statement [Visual Basic], Try...Catch...Finally
- Finally keyword [Visual Basic], Try...Catch...Finally
- Catch statement [Visual Basic]
- When keyword [Visual Basic]
- Visual Basic code, handling errors while running
- structured exception handling, Try...Catch...Finally statements
ms.assetid: d6488026-ccb3-42b8-a810-0d97b9d6472b
ms.openlocfilehash: 22f1611786a3da512632b5b547b7ef141c8f65c6
ms.sourcegitcommit: f8c270376ed905f6a8896ce0fe25b4f4b38ff498
ms.translationtype: MT
ms.contentlocale: ko-KR
ms.lasthandoff: 06/04/2020
ms.locfileid: "84391770"
---
# <a name="trycatchfinally-statement-visual-basic"></a><span data-ttu-id="49f62-103">Try...Catch...Finally 문(Visual Basic)</span><span class="sxs-lookup"><span data-stu-id="49f62-103">Try...Catch...Finally Statement (Visual Basic)</span></span>

<span data-ttu-id="49f62-104">코드를 계속 실행 하면서 지정 된 코드 블록에서 발생할 수 있는 일부 또는 모든 오류를 처리 하는 방법을 제공 합니다.</span><span class="sxs-lookup"><span data-stu-id="49f62-104">Provides a way to handle some or all possible errors that may occur in a given block of code, while still running code.</span></span>

## <a name="syntax"></a><span data-ttu-id="49f62-105">구문</span><span class="sxs-lookup"><span data-stu-id="49f62-105">Syntax</span></span>

```vb
Try
    [ tryStatements ]
    [ Exit Try ]
[ Catch [ exception [ As type ] ] [ When expression ]
    [ catchStatements ]
    [ Exit Try ] ]
[ Catch ... ]
[ Finally
    [ finallyStatements ] ]
End Try
```

## <a name="parts"></a><span data-ttu-id="49f62-106">부분</span><span class="sxs-lookup"><span data-stu-id="49f62-106">Parts</span></span>

|<span data-ttu-id="49f62-107">용어</span><span class="sxs-lookup"><span data-stu-id="49f62-107">Term</span></span>|<span data-ttu-id="49f62-108">정의</span><span class="sxs-lookup"><span data-stu-id="49f62-108">Definition</span></span>|
|---|---|
|`tryStatements`|<span data-ttu-id="49f62-109">선택 사항입니다.</span><span class="sxs-lookup"><span data-stu-id="49f62-109">Optional.</span></span> <span data-ttu-id="49f62-110">오류가 발생할 수 있는 문입니다.</span><span class="sxs-lookup"><span data-stu-id="49f62-110">Statement(s) where an error can occur.</span></span> <span data-ttu-id="49f62-111">복합 문일 수 있습니다.</span><span class="sxs-lookup"><span data-stu-id="49f62-111">Can be a compound statement.</span></span>|
|`Catch`|<span data-ttu-id="49f62-112">선택 사항입니다.</span><span class="sxs-lookup"><span data-stu-id="49f62-112">Optional.</span></span> <span data-ttu-id="49f62-113">여러 `Catch` 블록을 사용할 수 있습니다.</span><span class="sxs-lookup"><span data-stu-id="49f62-113">Multiple `Catch` blocks permitted.</span></span> <span data-ttu-id="49f62-114">블록을 처리할 때 예외가 발생 하는 경우에는 `Try` 각 `Catch` 문이 throw 된 예외를 나타내는를 사용 하 여 예외를 처리 하는지 여부를 확인 하기 위해 텍스트 순서로 검사 됩니다 `exception` .</span><span class="sxs-lookup"><span data-stu-id="49f62-114">If an exception occurs when processing the `Try` block, each `Catch` statement is examined in textual order to determine whether it handles the exception, with `exception` representing the exception that has been thrown.</span></span>|
|`exception`|<span data-ttu-id="49f62-115">선택 사항입니다.</span><span class="sxs-lookup"><span data-stu-id="49f62-115">Optional.</span></span> <span data-ttu-id="49f62-116">임의의 변수 이름입니다.</span><span class="sxs-lookup"><span data-stu-id="49f62-116">Any variable name.</span></span> <span data-ttu-id="49f62-117">`exception`의 초기 값은 throw된 오류 값입니다.</span><span class="sxs-lookup"><span data-stu-id="49f62-117">The initial value of `exception` is the value of the thrown error.</span></span> <span data-ttu-id="49f62-118">에서 `Catch` 발생 하는 오류를 지정 하는 데 사용 됩니다.</span><span class="sxs-lookup"><span data-stu-id="49f62-118">Used with `Catch` to specify the error caught.</span></span> <span data-ttu-id="49f62-119">생략 하는 경우 `Catch` 문은 예외를 catch 합니다.</span><span class="sxs-lookup"><span data-stu-id="49f62-119">If omitted, the `Catch` statement catches any exception.</span></span>|
|`type`|<span data-ttu-id="49f62-120">선택 사항입니다.</span><span class="sxs-lookup"><span data-stu-id="49f62-120">Optional.</span></span> <span data-ttu-id="49f62-121">클래스 필터의 유형을 지정 합니다.</span><span class="sxs-lookup"><span data-stu-id="49f62-121">Specifies the type of class filter.</span></span> <span data-ttu-id="49f62-122">의 값 `exception` 이 또는 파생 형식의로 지정 된 형식인 경우 `type` 식별자는 예외 개체에 바인딩됩니다.</span><span class="sxs-lookup"><span data-stu-id="49f62-122">If the value of `exception` is of the type specified by `type` or of a derived type, the identifier becomes bound to the exception object.</span></span>|
|`When`|<span data-ttu-id="49f62-123">선택 사항입니다.</span><span class="sxs-lookup"><span data-stu-id="49f62-123">Optional.</span></span> <span data-ttu-id="49f62-124">`Catch`절이 있는 문은 `When` 가로 계산 되는 경우에만 예외 `expression` 를 catch `True` 합니다.</span><span class="sxs-lookup"><span data-stu-id="49f62-124">A `Catch` statement with a `When` clause catches exceptions only when `expression` evaluates to `True`.</span></span> <span data-ttu-id="49f62-125">`When`절은 예외 형식을 확인 한 후에만 적용 되며 `expression` 예외를 나타내는 식별자를 참조할 수 있습니다.</span><span class="sxs-lookup"><span data-stu-id="49f62-125">A `When` clause is applied only after checking the type of the exception, and `expression` may refer to the identifier representing the exception.</span></span>|
|`expression`|<span data-ttu-id="49f62-126">선택 사항입니다.</span><span class="sxs-lookup"><span data-stu-id="49f62-126">Optional.</span></span> <span data-ttu-id="49f62-127">는로 암시적으로 변환할 수 있어야 합니다 `Boolean` .</span><span class="sxs-lookup"><span data-stu-id="49f62-127">Must be implicitly convertible to `Boolean`.</span></span> <span data-ttu-id="49f62-128">제네릭 필터를 설명 하는 식입니다.</span><span class="sxs-lookup"><span data-stu-id="49f62-128">Any expression that describes a generic filter.</span></span> <span data-ttu-id="49f62-129">일반적으로 오류 번호로 필터링 하는 데 사용 됩니다.</span><span class="sxs-lookup"><span data-stu-id="49f62-129">Typically used to filter by error number.</span></span> <span data-ttu-id="49f62-130">With `When` 키워드를 사용 하 여 오류가 발생 하는 상황을 지정 합니다.</span><span class="sxs-lookup"><span data-stu-id="49f62-130">Used with `When` keyword to specify circumstances under which the error is caught.</span></span>|
|`catchStatements`|<span data-ttu-id="49f62-131">선택 사항입니다.</span><span class="sxs-lookup"><span data-stu-id="49f62-131">Optional.</span></span> <span data-ttu-id="49f62-132">연결 된 블록에서 발생 하는 오류를 처리 하는 문 `Try` 입니다.</span><span class="sxs-lookup"><span data-stu-id="49f62-132">Statement(s) to handle errors that occur in the associated `Try` block.</span></span> <span data-ttu-id="49f62-133">복합 문일 수 있습니다.</span><span class="sxs-lookup"><span data-stu-id="49f62-133">Can be a compound statement.</span></span>|
|`Exit Try`|<span data-ttu-id="49f62-134">선택 사항입니다.</span><span class="sxs-lookup"><span data-stu-id="49f62-134">Optional.</span></span> <span data-ttu-id="49f62-135">구조에서 중단 되는 키워드입니다 `Try...Catch...Finally` .</span><span class="sxs-lookup"><span data-stu-id="49f62-135">Keyword that breaks out of the `Try...Catch...Finally` structure.</span></span> <span data-ttu-id="49f62-136">문 바로 다음에 오는 코드를 사용 하 여 실행을 다시 시작 `End Try` 합니다.</span><span class="sxs-lookup"><span data-stu-id="49f62-136">Execution resumes with the code immediately following the `End Try` statement.</span></span> <span data-ttu-id="49f62-137">`Finally`문은 계속 실행 됩니다.</span><span class="sxs-lookup"><span data-stu-id="49f62-137">The `Finally` statement will still be executed.</span></span> <span data-ttu-id="49f62-138">블록에는 허용 되지 않습니다 `Finally` .</span><span class="sxs-lookup"><span data-stu-id="49f62-138">Not allowed in `Finally` blocks.</span></span>|
|`Finally`|<span data-ttu-id="49f62-139">선택 사항입니다.</span><span class="sxs-lookup"><span data-stu-id="49f62-139">Optional.</span></span> <span data-ttu-id="49f62-140">`Finally`블록은 실행이 문의 일부를 떠날 때 항상 실행 됩니다 `Try...Catch` .</span><span class="sxs-lookup"><span data-stu-id="49f62-140">A `Finally` block is always executed when execution leaves any part of the `Try...Catch` statement.</span></span>|
|`finallyStatements`|<span data-ttu-id="49f62-141">선택 사항입니다.</span><span class="sxs-lookup"><span data-stu-id="49f62-141">Optional.</span></span> <span data-ttu-id="49f62-142">다른 모든 오류 처리가 발생 한 후 실행 되는 문입니다.</span><span class="sxs-lookup"><span data-stu-id="49f62-142">Statement(s) that are executed after all other error processing has occurred.</span></span>|
|`End Try`|<span data-ttu-id="49f62-143">구조를 종료 `Try...Catch...Finally` 합니다.</span><span class="sxs-lookup"><span data-stu-id="49f62-143">Terminates the `Try...Catch...Finally` structure.</span></span>|

## <a name="remarks"></a><span data-ttu-id="49f62-144">설명</span><span class="sxs-lookup"><span data-stu-id="49f62-144">Remarks</span></span>

<span data-ttu-id="49f62-145">특정 코드 섹션 중 특정 예외가 발생할 것으로 생각 되는 경우 코드를 블록에 배치 하 `Try` 고 블록을 사용 하 여 `Catch` 제어를 유지 하 고 예외가 발생 하면 예외를 처리 합니다.</span><span class="sxs-lookup"><span data-stu-id="49f62-145">If you expect that a particular exception might occur during a particular section of code, put the code in a `Try` block and use a `Catch` block to retain control and handle the exception if it occurs.</span></span>

<span data-ttu-id="49f62-146">`Try…Catch`문은 블록으로 구성 `Try` 되 고 그 뒤에 `Catch` 여러 가지 예외에 대 한 처리기를 지정 하는 절이 하나 이상 나옵니다.</span><span class="sxs-lookup"><span data-stu-id="49f62-146">A `Try…Catch` statement consists of a `Try` block followed by one or more `Catch` clauses, which specify handlers for various exceptions.</span></span> <span data-ttu-id="49f62-147">블록에서 예외가 throw 되 면 `Try` Visual Basic는 `Catch` 예외를 처리 하는 문을 찾습니다.</span><span class="sxs-lookup"><span data-stu-id="49f62-147">When an exception is thrown in a `Try` block, Visual Basic looks for the `Catch` statement that handles the exception.</span></span> <span data-ttu-id="49f62-148">일치 하는 `Catch` 문이 없는 경우 Visual Basic는 현재 메서드를 호출한 메서드를 검사 하 여 호출 스택을 확인 합니다.</span><span class="sxs-lookup"><span data-stu-id="49f62-148">If a matching `Catch` statement is not found, Visual Basic examines the method that called the current method, and so on up the call stack.</span></span> <span data-ttu-id="49f62-149">블록을 `Catch` 찾을 수 없는 경우 Visual Basic는 처리 되지 않은 예외 메시지를 사용자에 게 표시 하 고 프로그램의 실행을 중지 합니다.</span><span class="sxs-lookup"><span data-stu-id="49f62-149">If no `Catch` block is found, Visual Basic displays an unhandled exception message to the user and stops execution of the program.</span></span>

<span data-ttu-id="49f62-150">문에서 둘 이상의 문을 사용할 수 있습니다 `Catch` `Try…Catch` .</span><span class="sxs-lookup"><span data-stu-id="49f62-150">You can use more than one `Catch` statement in a `Try…Catch` statement.</span></span> <span data-ttu-id="49f62-151">이 작업을 수행 하는 경우 순서 대로 `Catch` 검사 되므로 절의 순서가 중요 합니다.</span><span class="sxs-lookup"><span data-stu-id="49f62-151">If you do this, the order of the `Catch` clauses is significant because they are examined in order.</span></span> <span data-ttu-id="49f62-152">더 구체적인 예외를 덜 구체적인 예외보다 먼저 catch합니다.</span><span class="sxs-lookup"><span data-stu-id="49f62-152">Catch the more specific exceptions before the less specific ones.</span></span>

<span data-ttu-id="49f62-153">다음 `Catch` 문 조건은 가장 구체적이 지 않으며 클래스에서 파생 되는 모든 예외를 catch 합니다 <xref:System.Exception> .</span><span class="sxs-lookup"><span data-stu-id="49f62-153">The following `Catch` statement conditions are the least specific, and will catch all exceptions that derive from the <xref:System.Exception> class.</span></span> <span data-ttu-id="49f62-154">일반적으로 이러한 변형 중 하나를 구조체의 마지막 블록으로 사용 하 `Catch` `Try...Catch...Finally` 고, 원하는 모든 예외를 catch 한 후에 사용 해야 합니다.</span><span class="sxs-lookup"><span data-stu-id="49f62-154">You should ordinarily use one of these variations as the last `Catch` block in the `Try...Catch...Finally` structure, after catching all the specific exceptions you expect.</span></span> <span data-ttu-id="49f62-155">제어 흐름은 `Catch` 이러한 변형 중 하나를 따르는 블록에 도달할 수 없습니다.</span><span class="sxs-lookup"><span data-stu-id="49f62-155">Control flow can never reach a `Catch` block that follows either of these variations.</span></span>

- <span data-ttu-id="49f62-156">는 `type` 입니다 `Exception` . 예를 들면 다음과 같습니다.`Catch ex As Exception`</span><span class="sxs-lookup"><span data-stu-id="49f62-156">The `type` is `Exception`, for example: `Catch ex As Exception`</span></span>

- <span data-ttu-id="49f62-157">문에 `exception` 변수가 없습니다. 예를 들면 다음과 같습니다.`Catch`</span><span class="sxs-lookup"><span data-stu-id="49f62-157">The statement has no `exception` variable, for example: `Catch`</span></span>

<span data-ttu-id="49f62-158">`Try…Catch…Finally`문이 다른 블록에 중첩 된 경우 `Try` Visual Basic `Catch` 가장 안쪽 블록의 각 문을 먼저 검사 `Try` 합니다.</span><span class="sxs-lookup"><span data-stu-id="49f62-158">When a `Try…Catch…Finally` statement is nested in another `Try` block, Visual Basic first examines each `Catch` statement in the innermost `Try` block.</span></span> <span data-ttu-id="49f62-159">일치 하 `Catch` 는 문이 없는 경우 검색은 `Catch` 외부 블록의 문으로 진행 됩니다 `Try…Catch…Finally` .</span><span class="sxs-lookup"><span data-stu-id="49f62-159">If no matching `Catch` statement is found, the search proceeds to the `Catch` statements of the outer `Try…Catch…Finally` block.</span></span>

<span data-ttu-id="49f62-160">블록의 지역 변수는 `Try` `Catch` 별도의 블록 이므로 블록에서 사용할 수 없습니다.</span><span class="sxs-lookup"><span data-stu-id="49f62-160">Local variables from a `Try` block are not available in a `Catch` block because they are separate blocks.</span></span> <span data-ttu-id="49f62-161">둘 이상의 블록에서 변수를 사용 하려면 구조체 외부에서 변수를 선언 합니다 `Try...Catch...Finally` .</span><span class="sxs-lookup"><span data-stu-id="49f62-161">If you want to use a variable in more than one block, declare the variable outside the `Try...Catch...Finally` structure.</span></span>

> [!TIP]
> <span data-ttu-id="49f62-162">`Try…Catch…Finally`문은 IntelliSense 코드 조각으로 사용할 수 있습니다.</span><span class="sxs-lookup"><span data-stu-id="49f62-162">The `Try…Catch…Finally` statement is available as an IntelliSense code snippet.</span></span> <span data-ttu-id="49f62-163">코드 조각 관리자에서 코드 패턴을 확장 합니다. **For Each, Try Catch, Property 등**, **오류 처리 (예외)** 를 차례로 클릭 합니다.</span><span class="sxs-lookup"><span data-stu-id="49f62-163">In the Code Snippets Manager, expand **Code Patterns - If, For Each, Try Catch, Property, etc**, and then **Error Handling (Exceptions)**.</span></span> <span data-ttu-id="49f62-164">자세한 내용은 [코드 조각](/visualstudio/ide/code-snippets)을 참조하세요.</span><span class="sxs-lookup"><span data-stu-id="49f62-164">For more information, see [Code Snippets](/visualstudio/ide/code-snippets).</span></span>

## <a name="finally-block"></a><span data-ttu-id="49f62-165">Finally 블록</span><span class="sxs-lookup"><span data-stu-id="49f62-165">Finally block</span></span>

<span data-ttu-id="49f62-166">구조를 종료 하기 전에 실행 해야 하는 문이 하나 이상 있는 경우 `Try` 블록을 사용 `Finally` 합니다.</span><span class="sxs-lookup"><span data-stu-id="49f62-166">If you have one or more statements that must run before you exit the `Try` structure, use a `Finally` block.</span></span> <span data-ttu-id="49f62-167">컨트롤이 `Finally` 구조 외부로 전달 되기 직전에 블록으로 전달 `Try…Catch` 됩니다.</span><span class="sxs-lookup"><span data-stu-id="49f62-167">Control passes to the `Finally` block just before it passes out of the `Try…Catch` structure.</span></span> <span data-ttu-id="49f62-168">이는 구조 내에서 예외가 발생 하는 경우에도 마찬가지입니다 `Try` .</span><span class="sxs-lookup"><span data-stu-id="49f62-168">This is true even if an exception occurs anywhere inside the `Try` structure.</span></span>

<span data-ttu-id="49f62-169">`Finally`블록은 예외가 있는 경우에도 실행 해야 하는 모든 코드를 실행 하는 데 유용 합니다.</span><span class="sxs-lookup"><span data-stu-id="49f62-169">A `Finally` block is useful for running any code that must execute even if there is an exception.</span></span> <span data-ttu-id="49f62-170">컨트롤은 `Finally` 블록이 종료 되는 방법에 관계 없이 블록으로 전달 됩니다 `Try...Catch` .</span><span class="sxs-lookup"><span data-stu-id="49f62-170">Control is passed to the `Finally` block regardless of how the `Try...Catch` block exits.</span></span>

<span data-ttu-id="49f62-171">`Finally`코드에서 `Return` 또는 블록의 문이 발견 되는 경우에도 블록의 코드가 실행 됩니다 `Try` `Catch` .</span><span class="sxs-lookup"><span data-stu-id="49f62-171">The code in a `Finally` block runs even if your code encounters a `Return` statement in a `Try` or `Catch` block.</span></span> <span data-ttu-id="49f62-172">제어는 `Try` `Catch` `Finally` 다음과 같은 경우에 또는 블록에서 해당 블록으로 전달 되지 않습니다.</span><span class="sxs-lookup"><span data-stu-id="49f62-172">Control does not pass from a `Try` or `Catch` block to the corresponding `Finally` block in the following cases:</span></span>

- <span data-ttu-id="49f62-173">또는 블록에서 [End 문이](end-statement.md) 발견 되었습니다 `Try` `Catch` .</span><span class="sxs-lookup"><span data-stu-id="49f62-173">An [End Statement](end-statement.md) is encountered in the `Try` or `Catch` block.</span></span>

- <span data-ttu-id="49f62-174"><xref:System.StackOverflowException>또는 블록에서이 throw `Try` 됩니다 `Catch` .</span><span class="sxs-lookup"><span data-stu-id="49f62-174">A <xref:System.StackOverflowException> is thrown in the `Try` or `Catch` block.</span></span>

<span data-ttu-id="49f62-175">명시적으로 실행을 블록으로 전송 하는 것은 유효 하지 않습니다 `Finally` .</span><span class="sxs-lookup"><span data-stu-id="49f62-175">It is not valid to explicitly transfer execution into a `Finally` block.</span></span> <span data-ttu-id="49f62-176">`Finally`예외를 제외 하 고는 블록 외부로의 실행 전송이 올바르지 않습니다.</span><span class="sxs-lookup"><span data-stu-id="49f62-176">Transferring execution out of a `Finally` block is not valid, except through an exception.</span></span>

<span data-ttu-id="49f62-177">`Try`문에 블록이 하나 이상 포함 되어 있지 않으면 `Catch` 블록을 포함 해야 합니다 `Finally` .</span><span class="sxs-lookup"><span data-stu-id="49f62-177">If a `Try` statement does not contain at least one `Catch` block, it must contain a `Finally` block.</span></span>

> [!TIP]
> <span data-ttu-id="49f62-178">특정 예외를 catch 하지 않아도 되는 경우이 문은 블록을 `Using` `Try…Finally` 종료 하는 방법에 관계 없이 블록 처럼 동작 하 고 리소스 삭제를 보장 합니다.</span><span class="sxs-lookup"><span data-stu-id="49f62-178">If you do not have to catch specific exceptions, the `Using` statement behaves like a `Try…Finally` block, and guarantees disposal of the resources, regardless of how you exit the block.</span></span> <span data-ttu-id="49f62-179">처리 되지 않은 예외가 있는 경우에도 마찬가지입니다.</span><span class="sxs-lookup"><span data-stu-id="49f62-179">This is true even with an unhandled exception.</span></span> <span data-ttu-id="49f62-180">자세한 내용은 [Using 문](using-statement.md)을 참조 하세요.</span><span class="sxs-lookup"><span data-stu-id="49f62-180">For more information, see [Using Statement](using-statement.md).</span></span>

## <a name="exception-argument"></a><span data-ttu-id="49f62-181">예외 인수</span><span class="sxs-lookup"><span data-stu-id="49f62-181">Exception argument</span></span>

<span data-ttu-id="49f62-182">`Catch`Block 인수는 클래스 `exception` 의 인스턴스이거나 클래스 <xref:System.Exception> 에서 파생 되는 클래스입니다 `Exception` .</span><span class="sxs-lookup"><span data-stu-id="49f62-182">The `Catch` block `exception` argument is an instance of the <xref:System.Exception> class or a class that derives from the `Exception` class.</span></span> <span data-ttu-id="49f62-183">`Exception`클래스 인스턴스는 블록에서 발생 한 오류에 해당 합니다 `Try` .</span><span class="sxs-lookup"><span data-stu-id="49f62-183">The `Exception` class instance corresponds to the error that occurred in the `Try` block.</span></span>

<span data-ttu-id="49f62-184">개체의 속성은 `Exception` 예외의 원인과 위치를 식별 하는 데 도움이 됩니다.</span><span class="sxs-lookup"><span data-stu-id="49f62-184">The properties of the `Exception` object help to identify the cause and location of an exception.</span></span> <span data-ttu-id="49f62-185">예를 들어 <xref:System.Exception.StackTrace%2A> 속성은 예외를 발생 시킨 호출 된 메서드를 나열 하 여 코드에서 오류가 발생 한 위치를 찾을 수 있도록 합니다.</span><span class="sxs-lookup"><span data-stu-id="49f62-185">For example, the <xref:System.Exception.StackTrace%2A> property lists the called methods that led to the exception, helping you find where the error occurred in the code.</span></span> <span data-ttu-id="49f62-186"><xref:System.Exception.Message%2A>예외를 설명 하는 메시지를 반환 합니다.</span><span class="sxs-lookup"><span data-stu-id="49f62-186"><xref:System.Exception.Message%2A> returns a message that describes the exception.</span></span> <span data-ttu-id="49f62-187"><xref:System.Exception.HelpLink%2A>연결 된 도움말 파일에 대 한 링크를 반환 합니다.</span><span class="sxs-lookup"><span data-stu-id="49f62-187"><xref:System.Exception.HelpLink%2A> returns a link to an associated Help file.</span></span> <span data-ttu-id="49f62-188"><xref:System.Exception.InnerException%2A>`Exception`현재 예외를 발생 시킨 개체를 반환 하거나, 원래이 없으면를 반환 합니다 `Nothing` `Exception` .</span><span class="sxs-lookup"><span data-stu-id="49f62-188"><xref:System.Exception.InnerException%2A> returns the `Exception` object that caused the current exception, or it returns `Nothing` if there is no original `Exception`.</span></span>

## <a name="considerations-when-using-a-trycatch-statement"></a><span data-ttu-id="49f62-189">Try 사용 시 고려 사항 ... Catch 문</span><span class="sxs-lookup"><span data-stu-id="49f62-189">Considerations when using a Try…Catch statement</span></span>

<span data-ttu-id="49f62-190">문을 사용 `Try…Catch` 하 여 비정상적인 또는 예기치 않은 프로그램 이벤트의 발생을 신호로 알립니다.</span><span class="sxs-lookup"><span data-stu-id="49f62-190">Use a `Try…Catch` statement only to signal the occurrence of unusual or unanticipated program events.</span></span> <span data-ttu-id="49f62-191">이러한 이유는 다음과 같습니다.</span><span class="sxs-lookup"><span data-stu-id="49f62-191">Reasons for this include the following:</span></span>

- <span data-ttu-id="49f62-192">런타임에 예외를 catch 하면 추가 오버 헤드가 발생 하며 예외를 방지 하기 위해 사전 검사 보다 속도가 느려질 수 있습니다.</span><span class="sxs-lookup"><span data-stu-id="49f62-192">Catching exceptions at runtime creates additional overhead, and is likely to be slower than pre-checking to avoid exceptions.</span></span>

- <span data-ttu-id="49f62-193">`Catch`블록이 올바르게 처리 되지 않은 경우 예외가 사용자에 게 올바르게 보고 되지 않을 수 있습니다.</span><span class="sxs-lookup"><span data-stu-id="49f62-193">If a `Catch` block is not handled correctly, the exception might not be reported correctly to users.</span></span>

- <span data-ttu-id="49f62-194">예외 처리는 프로그램을 더 복잡 하 게 만듭니다.</span><span class="sxs-lookup"><span data-stu-id="49f62-194">Exception handling makes a program more complex.</span></span>

<span data-ttu-id="49f62-195">`Try…Catch`발생할 가능성이 있는 조건을 확인 하는 문은 항상 필요 하지 않습니다.</span><span class="sxs-lookup"><span data-stu-id="49f62-195">You do not always need a `Try…Catch` statement to check for a condition that is likely to occur.</span></span> <span data-ttu-id="49f62-196">다음 예에서는 파일을 열기 전에 파일이 있는지 여부를 확인 합니다.</span><span class="sxs-lookup"><span data-stu-id="49f62-196">The following example checks whether a file exists before trying to open it.</span></span> <span data-ttu-id="49f62-197">이렇게 하면 메서드에서 throw 된 예외를 catch 할 필요가 줄어듭니다 <xref:System.IO.File.OpenText%2A> .</span><span class="sxs-lookup"><span data-stu-id="49f62-197">This reduces the need for catching an exception thrown by the <xref:System.IO.File.OpenText%2A> method.</span></span>

[!code-vb[VbVbalrStatements#94](~/samples/snippets/visualbasic/VS_Snippets_VBCSharp/VbVbalrStatements/VB/Class1.vb#94)]

<span data-ttu-id="49f62-198">`Catch`스레드로부터 안전한 로깅 또는 적절 한 메시지를 통해 블록의 코드가 사용자에 게 예외를 올바르게 보고할 수 있는지 확인 합니다.</span><span class="sxs-lookup"><span data-stu-id="49f62-198">Ensure that code in `Catch` blocks can properly report exceptions to users, whether through thread-safe logging or appropriate messages.</span></span> <span data-ttu-id="49f62-199">그렇지 않으면 예외를 알 수 없는 상태로 유지할 수 있습니다.</span><span class="sxs-lookup"><span data-stu-id="49f62-199">Otherwise, exceptions might remain unknown.</span></span>

## <a name="async-methods"></a><span data-ttu-id="49f62-200">비동기 메서드</span><span class="sxs-lookup"><span data-stu-id="49f62-200">Async methods</span></span>

<span data-ttu-id="49f62-201">[비동기](../modifiers/async.md) 한정자를 사용 하 여 메서드를 표시 하는 경우 메서드에서 [wait](../operators/await-operator.md) 연산자를 사용할 수 있습니다.</span><span class="sxs-lookup"><span data-stu-id="49f62-201">If you mark a method with the [Async](../modifiers/async.md) modifier, you can use the [Await](../operators/await-operator.md) operator in the method.</span></span> <span data-ttu-id="49f62-202">연산자가 있는 문은 `Await` 대기 작업이 완료 될 때까지 메서드 실행을 일시 중단 합니다.</span><span class="sxs-lookup"><span data-stu-id="49f62-202">A statement with the `Await` operator suspends execution of the method until the awaited task completes.</span></span> <span data-ttu-id="49f62-203">작업은 진행 중인 작업을 나타냅니다.</span><span class="sxs-lookup"><span data-stu-id="49f62-203">The task represents ongoing work.</span></span> <span data-ttu-id="49f62-204">연산자와 연결 된 작업이 완료 되 면 `Await` 동일한 메서드에서 실행이 다시 시작 됩니다.</span><span class="sxs-lookup"><span data-stu-id="49f62-204">When the task that's associated with the `Await` operator finishes, execution resumes in the same method.</span></span> <span data-ttu-id="49f62-205">자세한 내용은 [비동기 프로그램의 제어 흐름](../../programming-guide/concepts/async/control-flow-in-async-programs.md)을 참조 하세요.</span><span class="sxs-lookup"><span data-stu-id="49f62-205">For more information, see [Control Flow in Async Programs](../../programming-guide/concepts/async/control-flow-in-async-programs.md).</span></span>

<span data-ttu-id="49f62-206">비동기 메서드에서 반환 되는 작업은 처리 되지 않은 예외로 인해 완료 되었음을 나타내는 오류가 발생 한 상태로 종료 될 수 있습니다.</span><span class="sxs-lookup"><span data-stu-id="49f62-206">A task returned by an Async method may end in a faulted state, indicating that it completed due to an unhandled exception.</span></span> <span data-ttu-id="49f62-207">작업은 취소 됨 상태로 종료 될 수도 있으며,이로 인해 `OperationCanceledException` wait 식에서 예외가 발생 합니다.</span><span class="sxs-lookup"><span data-stu-id="49f62-207">A task may also end in a canceled state, which results in an `OperationCanceledException` being thrown out of the await expression.</span></span> <span data-ttu-id="49f62-208">두 종류의 예외를 catch 하려면 `Await` 작업과 연결 된 식을 블록에 놓고 `Try` 블록에서 예외를 catch 합니다 `Catch` .</span><span class="sxs-lookup"><span data-stu-id="49f62-208">To catch either type of exception, place the `Await` expression that's associated with the task in a `Try` block, and catch the exception in the `Catch` block.</span></span> <span data-ttu-id="49f62-209">예제는이 항목의 뒷부분에 나와 있습니다.</span><span class="sxs-lookup"><span data-stu-id="49f62-209">An example is provided later in this topic.</span></span>

<span data-ttu-id="49f62-210">여러 예외로 인해 오류가 발생 했기 때문에 작업이 오류 상태에 있을 수 있습니다.</span><span class="sxs-lookup"><span data-stu-id="49f62-210">A task can be in a faulted state because multiple exceptions were responsible for its faulting.</span></span> <span data-ttu-id="49f62-211">예를 들어 작업은 <xref:System.Threading.Tasks.Task.WhenAll%2A?displayProperty=nameWithType> 호출의 결과일 수 있습니다.</span><span class="sxs-lookup"><span data-stu-id="49f62-211">For example, the task might be the result of a call to <xref:System.Threading.Tasks.Task.WhenAll%2A?displayProperty=nameWithType>.</span></span> <span data-ttu-id="49f62-212">이러한 작업을 기다릴 때 catch 된 예외는 예외 중 하나일 뿐 이며 catch 할 예외를 예측할 수 없습니다.</span><span class="sxs-lookup"><span data-stu-id="49f62-212">When you await such a task, the caught exception is only one of the exceptions, and you can't predict which exception will be caught.</span></span> <span data-ttu-id="49f62-213">예제는이 항목의 뒷부분에 나와 있습니다.</span><span class="sxs-lookup"><span data-stu-id="49f62-213">An example is provided later in this topic.</span></span>

<span data-ttu-id="49f62-214">`Await`식은 `Catch` 블록이 나 블록 안에 있을 수 없습니다 `Finally` .</span><span class="sxs-lookup"><span data-stu-id="49f62-214">An `Await` expression can't be inside a `Catch` block or `Finally` block.</span></span>

## <a name="iterators"></a><span data-ttu-id="49f62-215">반복기</span><span class="sxs-lookup"><span data-stu-id="49f62-215">Iterators</span></span>

<span data-ttu-id="49f62-216">반복기 함수 또는 `Get` 접근자는 컬렉션에 대해 사용자 지정 반복을 수행 합니다.</span><span class="sxs-lookup"><span data-stu-id="49f62-216">An iterator function or `Get` accessor performs a custom iteration over a collection.</span></span> <span data-ttu-id="49f62-217">반복기는 [Yield](yield-statement.md) 문을 사용 하 여 컬렉션의 각 요소를 한 번에 하나씩 반환 합니다.</span><span class="sxs-lookup"><span data-stu-id="49f62-217">An iterator uses a [Yield](yield-statement.md) statement to return each element of the collection one at a time.</span></span> <span data-ttu-id="49f62-218">For Each ...를 사용 하 여 반복기 함수를 호출 합니다. [ 다음 문](for-each-next-statement.md).</span><span class="sxs-lookup"><span data-stu-id="49f62-218">You call an iterator function by using a [For Each...Next Statement](for-each-next-statement.md).</span></span>

<span data-ttu-id="49f62-219">`Yield`문은 블록 내부에 있을 수 있습니다 `Try` .</span><span class="sxs-lookup"><span data-stu-id="49f62-219">A `Yield` statement can be inside a `Try` block.</span></span> <span data-ttu-id="49f62-220">`Try`문이 포함 된 블록은 블록 `Yield` 을 포함할 수 있으며 `Catch` 블록을 포함할 수 있습니다 `Finally` .</span><span class="sxs-lookup"><span data-stu-id="49f62-220">A `Try` block that contains a `Yield` statement can have `Catch` blocks, and can have a `Finally` block.</span></span> <span data-ttu-id="49f62-221">예제는 [반복기](../../programming-guide/concepts/iterators.md) 의 "Try 블록 Visual Basic" 섹션을 참조 하세요.</span><span class="sxs-lookup"><span data-stu-id="49f62-221">See the "Try Blocks in Visual Basic" section of [Iterators](../../programming-guide/concepts/iterators.md) for an example.</span></span>

<span data-ttu-id="49f62-222">`Yield`문은 `Catch` 블록이 나 블록 안에 있을 수 없습니다 `Finally` .</span><span class="sxs-lookup"><span data-stu-id="49f62-222">A `Yield` statement cannot be inside a `Catch` block or a `Finally` block.</span></span>

<span data-ttu-id="49f62-223">`For Each`본문 (반복기 함수 외부)에서 예외를 throw 하는 경우 `Catch` 반복기 함수의 블록이 실행 되지 않지만 `Finally` 반복기 함수의 블록이 실행 됩니다.</span><span class="sxs-lookup"><span data-stu-id="49f62-223">If the `For Each` body (outside of the iterator function) throws an exception, a `Catch` block in the iterator function is not executed, but a `Finally` block in the iterator function is executed.</span></span> <span data-ttu-id="49f62-224">`Catch`반복기 함수 내의 블록은 반복기 함수 내에서 발생 하는 예외만 catch 합니다.</span><span class="sxs-lookup"><span data-stu-id="49f62-224">A `Catch` block inside an iterator function catches only exceptions that occur inside the iterator function.</span></span>

## <a name="partial-trust-situations"></a><span data-ttu-id="49f62-225">부분 신뢰 상황</span><span class="sxs-lookup"><span data-stu-id="49f62-225">Partial-trust situations</span></span>

<span data-ttu-id="49f62-226">네트워크 공유에서 호스트 되는 응용 프로그램과 같은 부분 신뢰 상황에서는 호출을 `Try...Catch...Finally` 포함 하는 메서드가 호출 되기 전에 발생 하는 보안 예외를 catch 하지 않습니다.</span><span class="sxs-lookup"><span data-stu-id="49f62-226">In partial-trust situations, such as an application hosted on a network share, `Try...Catch...Finally` does not catch security exceptions that occur before the method that contains the call is invoked.</span></span> <span data-ttu-id="49f62-227">다음 예제를 서버 공유에 배치 하 고 여기에서 실행 하면 "System.web Exception: Request Failed" 오류가 발생 합니다.</span><span class="sxs-lookup"><span data-stu-id="49f62-227">The following example, when you put it on a server share and run from there, produces the error "System.Security.SecurityException: Request Failed."</span></span> <span data-ttu-id="49f62-228">보안 예외에 대 한 자세한 내용은 클래스를 참조 하세요 <xref:System.Security.SecurityException> .</span><span class="sxs-lookup"><span data-stu-id="49f62-228">For more information about security exceptions, see the <xref:System.Security.SecurityException> class.</span></span>

[!code-vb[VbVbalrStatements#85](~/samples/snippets/visualbasic/VS_Snippets_VBCSharp/VbVbalrStatements/VB/Class1.vb#85)]

<span data-ttu-id="49f62-229">이러한 부분 신뢰 상황에서는 `Process.Start` 문을 별도의에 배치 해야 합니다 `Sub` .</span><span class="sxs-lookup"><span data-stu-id="49f62-229">In such a partial-trust situation, you have to put the `Process.Start` statement in a separate `Sub`.</span></span> <span data-ttu-id="49f62-230">에 대 한 초기 호출이 `Sub` 실패 합니다.</span><span class="sxs-lookup"><span data-stu-id="49f62-230">The initial call to the `Sub` will fail.</span></span> <span data-ttu-id="49f62-231">이를 통해를 `Try...Catch` `Sub` 포함 하는이 `Process.Start` 시작 되 고 보안 예외가 생성 되기 전에를 catch 할 수 있습니다.</span><span class="sxs-lookup"><span data-stu-id="49f62-231">This enables `Try...Catch` to catch it before the `Sub` that contains `Process.Start` is started and the security exception produced.</span></span>

## <a name="examples"></a><span data-ttu-id="49f62-232">예제</span><span class="sxs-lookup"><span data-stu-id="49f62-232">Examples</span></span>

### <a name="the-structure-of-trycatchfinally"></a><span data-ttu-id="49f62-233">Try ... Catch ... 마지막으로</span><span class="sxs-lookup"><span data-stu-id="49f62-233">The structure of Try...Catch...Finally</span></span>

<span data-ttu-id="49f62-234">다음 예에서는 문의 구조를 보여 줍니다 `Try...Catch...Finally` .</span><span class="sxs-lookup"><span data-stu-id="49f62-234">The following example illustrates the structure of the `Try...Catch...Finally` statement.</span></span>

[!code-vb[VbVbalrStatements#86](~/samples/snippets/visualbasic/VS_Snippets_VBCSharp/VbVbalrStatements/VB/Class1.vb#86)]  

### <a name="exception-in-a-method-called-from-a-try-block"></a><span data-ttu-id="49f62-235">Try 블록에서 호출 된 메서드에서 예외가 발생 했습니다.</span><span class="sxs-lookup"><span data-stu-id="49f62-235">Exception in a method called from a Try block</span></span>

<span data-ttu-id="49f62-236">다음 예제에서 `CreateException` 메서드는을 throw `NullReferenceException` 합니다.</span><span class="sxs-lookup"><span data-stu-id="49f62-236">In the following example, the `CreateException` method throws a `NullReferenceException`.</span></span> <span data-ttu-id="49f62-237">예외를 생성 하는 코드는 블록에 없습니다 `Try` .</span><span class="sxs-lookup"><span data-stu-id="49f62-237">The code that generates the exception is not in a `Try` block.</span></span> <span data-ttu-id="49f62-238">따라서 메서드는 `CreateException` 예외를 처리 하지 않습니다.</span><span class="sxs-lookup"><span data-stu-id="49f62-238">Therefore, the `CreateException` method does not handle the exception.</span></span> <span data-ttu-id="49f62-239">메서드에 `RunSample` 대 한 호출이 블록에 있기 때문에 메서드는 예외를 처리 합니다 `CreateException` `Try` .</span><span class="sxs-lookup"><span data-stu-id="49f62-239">The `RunSample` method does handle the exception because the call to the `CreateException` method is in a `Try` block.</span></span>

<span data-ttu-id="49f62-240">이 예제에는 `Catch` 가장 일반적인에서 가장 일반적인 순서로 정렬 된 여러 유형의 예외에 대 한 문이 포함 되어 있습니다.</span><span class="sxs-lookup"><span data-stu-id="49f62-240">The example includes `Catch` statements for several types of exceptions, ordered from the most specific to the most general.</span></span>

[!code-vb[VbVbalrStatements#91](~/samples/snippets/visualbasic/VS_Snippets_VBCSharp/VbVbalrStatements/VB/Class1.vb#91)]

### <a name="the-catch-when-statement"></a><span data-ttu-id="49f62-241">Catch When 문</span><span class="sxs-lookup"><span data-stu-id="49f62-241">The Catch When statement</span></span>

<span data-ttu-id="49f62-242">다음 예에서는 문을 사용 하 여 조건식을 필터링 하는 방법을 보여 줍니다 `Catch When` .</span><span class="sxs-lookup"><span data-stu-id="49f62-242">The following example shows how to use a `Catch When` statement to filter on a conditional expression.</span></span> <span data-ttu-id="49f62-243">조건식이로 평가 되 면 `True` 블록의 코드가 `Catch` 실행 됩니다.</span><span class="sxs-lookup"><span data-stu-id="49f62-243">If the conditional expression evaluates to `True`, the code in the `Catch` block runs.</span></span>

[!code-vb[VbVbalrStatements#92](~/samples/snippets/visualbasic/VS_Snippets_VBCSharp/VbVbalrStatements/VB/Class1.vb#92)]

### <a name="nested-try-statements"></a><span data-ttu-id="49f62-244">중첩 된 Try 문</span><span class="sxs-lookup"><span data-stu-id="49f62-244">Nested Try statements</span></span>

<span data-ttu-id="49f62-245">다음 예제에는 `Try…Catch` 블록에 포함 된 문이 있습니다 `Try` .</span><span class="sxs-lookup"><span data-stu-id="49f62-245">The following example has a `Try…Catch` statement that is contained in a `Try` block.</span></span> <span data-ttu-id="49f62-246">내부 `Catch` 블록은 `InnerException` 속성이 원래 예외로 설정 된 예외를 throw 합니다.</span><span class="sxs-lookup"><span data-stu-id="49f62-246">The inner `Catch` block throws an exception that has its `InnerException` property set to the original exception.</span></span> <span data-ttu-id="49f62-247">외부 `Catch` 블록은 자체 예외 및 내부 예외를 보고 합니다.</span><span class="sxs-lookup"><span data-stu-id="49f62-247">The outer `Catch` block reports its own exception and the inner exception.</span></span>

[!code-vb[VbVbalrStatements#93](~/samples/snippets/visualbasic/VS_Snippets_VBCSharp/VbVbalrStatements/VB/Class1.vb#93)]

### <a name="exception-handling-for-async-methods"></a><span data-ttu-id="49f62-248">비동기 메서드에 대 한 예외 처리</span><span class="sxs-lookup"><span data-stu-id="49f62-248">Exception handling for async methods</span></span>

<span data-ttu-id="49f62-249">다음 예제에서는 비동기 메서드에 대한 예외 처리를 보여 줍니다.</span><span class="sxs-lookup"><span data-stu-id="49f62-249">The following example illustrates exception handling for async methods.</span></span> <span data-ttu-id="49f62-250">비동기 작업에 적용 되는 예외를 catch 하기 위해 `Await` 식은 `Try` 호출자 블록에 있으며 예외는 블록에서 catch 됩니다 `Catch` .</span><span class="sxs-lookup"><span data-stu-id="49f62-250">To catch an exception that applies to an async task, the `Await` expression is in a `Try` block of the caller, and the exception is caught in the `Catch` block.</span></span>

<span data-ttu-id="49f62-251">예제에서 `Throw New Exception` 줄의 주석 처리를 제거하여 예외 처리를 보여 줍니다.</span><span class="sxs-lookup"><span data-stu-id="49f62-251">Uncomment the `Throw New Exception` line in the example to demonstrate exception handling.</span></span> <span data-ttu-id="49f62-252">블록에서 예외가 catch 되 고, `Catch` 작업의 `IsFaulted` 속성이로 설정 되 `True` 고, 작업의 `Exception.InnerException` 속성이 예외로 설정 됩니다.</span><span class="sxs-lookup"><span data-stu-id="49f62-252">The exception is caught in the `Catch` block, the task's `IsFaulted` property is set to `True`, and the task's `Exception.InnerException` property is set to the exception.</span></span>

<span data-ttu-id="49f62-253">`Throw New OperationCancelledException` 줄의 주석 처리를 제거하여 비동기 프로세스를 취소할 수 있을 때 발생하는 동작을 보여 줍니다.</span><span class="sxs-lookup"><span data-stu-id="49f62-253">Uncomment the `Throw New OperationCancelledException` line to demonstrate what happens when you cancel an asynchronous process.</span></span> <span data-ttu-id="49f62-254">블록에서 예외가 catch 되 `Catch` 고 작업의 `IsCanceled` 속성이로 설정 됩니다 `True` .</span><span class="sxs-lookup"><span data-stu-id="49f62-254">The exception is caught in the `Catch` block, and the task's `IsCanceled` property is set to `True`.</span></span> <span data-ttu-id="49f62-255">그러나이 예제에 적용 되지 않는 일부 조건에서는 `IsFaulted` 가로 설정 되 `True` 고 `IsCanceled` 가로 설정 됩니다 `False` .</span><span class="sxs-lookup"><span data-stu-id="49f62-255">However, under some conditions that don't apply to this example, `IsFaulted` is set to `True` and `IsCanceled` is set to `False`.</span></span>

[!code-vb[csAsyncExceptions#1](~/samples/snippets/visualbasic/VS_Snippets_VBCSharp/csasyncexceptions/vb/class1.vb#1)]

### <a name="handling-multiple-exceptions-in-async-methods"></a><span data-ttu-id="49f62-256">비동기 메서드에서 여러 예외 처리</span><span class="sxs-lookup"><span data-stu-id="49f62-256">Handling multiple exceptions in async methods</span></span>

<span data-ttu-id="49f62-257">다음 예제에서는 여러 작업에서 여러 예외가 발생할 수 있는 경우 예외 처리를 보여 줍니다.</span><span class="sxs-lookup"><span data-stu-id="49f62-257">The following example illustrates exception handling where multiple tasks can result in multiple exceptions.</span></span> <span data-ttu-id="49f62-258">`Try`블록은 `Await` 반환 된 작업에 대 한 식을 포함 합니다 <xref:System.Threading.Tasks.Task.WhenAll%2A?displayProperty=nameWithType> .</span><span class="sxs-lookup"><span data-stu-id="49f62-258">The `Try` block has the `Await` expression for the task that <xref:System.Threading.Tasks.Task.WhenAll%2A?displayProperty=nameWithType> returned.</span></span> <span data-ttu-id="49f62-259">이 작업이 적용 되는 세 가지 작업이 완료 되 면 작업이 완료 됩니다 <xref:System.Threading.Tasks.Task.WhenAll%2A?displayProperty=nameWithType> .</span><span class="sxs-lookup"><span data-stu-id="49f62-259">The task is complete when the three tasks to which <xref:System.Threading.Tasks.Task.WhenAll%2A?displayProperty=nameWithType> is applied are complete.</span></span>

<span data-ttu-id="49f62-260">세 작업에서 각각 예외가 발생합니다.</span><span class="sxs-lookup"><span data-stu-id="49f62-260">Each of the three tasks causes an exception.</span></span> <span data-ttu-id="49f62-261">`Catch`블록은 `Exception.InnerExceptions` 반환 된 작업의 속성에 있는 예외를 반복 합니다 `Task.WhenAll` .</span><span class="sxs-lookup"><span data-stu-id="49f62-261">The `Catch` block iterates through the exceptions, which are found in the `Exception.InnerExceptions` property of the task that `Task.WhenAll` returned.</span></span>

[!code-vb[csAsyncExceptions#3](~/samples/snippets/visualbasic/VS_Snippets_VBCSharp/csasyncexceptions/vb/class1.vb#3)]

## <a name="see-also"></a><span data-ttu-id="49f62-262">참고 항목</span><span class="sxs-lookup"><span data-stu-id="49f62-262">See also</span></span>

- <xref:Microsoft.VisualBasic.Information.Err%2A>
- <xref:System.Exception>
- [<span data-ttu-id="49f62-263">Exit 문</span><span class="sxs-lookup"><span data-stu-id="49f62-263">Exit Statement</span></span>](exit-statement.md)
- [<span data-ttu-id="49f62-264">On Error 문</span><span class="sxs-lookup"><span data-stu-id="49f62-264">On Error Statement</span></span>](on-error-statement.md)
- [<span data-ttu-id="49f62-265">코드 조각을 사용하는 방법에 대한 유용한 정보</span><span class="sxs-lookup"><span data-stu-id="49f62-265">Best Practices for Using Code Snippets</span></span>](/visualstudio/ide/best-practices-for-using-code-snippets)
- [<span data-ttu-id="49f62-266">예외 처리</span><span class="sxs-lookup"><span data-stu-id="49f62-266">Exception Handling</span></span>](../../../standard/parallel-programming/exception-handling-task-parallel-library.md)
- [<span data-ttu-id="49f62-267">Throw 문</span><span class="sxs-lookup"><span data-stu-id="49f62-267">Throw Statement</span></span>](throw-statement.md)
