---
title: "'Throw' 문은 'Catch' 문 외부 또는 'Finally' 문 내부에서 피연산자를 생략할 수 없습니다."
ms.date: 07/20/2015
f1_keywords:
- vbc30666
- bc30666
helpviewer_keywords:
- BC30666
ms.assetid: a208a6ea-0e36-4bf1-8984-4de1a0e38a2a
ms.openlocfilehash: 05fc14b0f493b3901fda9fbdba7e0fcebae6bea5
ms.sourcegitcommit: bf5c5850654187705bc94cc40ebfb62fe346ab02
ms.translationtype: MT
ms.contentlocale: ko-KR
ms.lasthandoff: 09/23/2020
ms.locfileid: "91068897"
---
# <a name="throw-statement-cannot-omit-operand-outside-a-catch-statement-or-inside-a-finally-statement"></a>'Throw' 문은 'Catch' 문 외부 또는 'Finally' 문 내부에서 피연산자를 생략할 수 없습니다.

`Throw` 문 외부의 `Catch` 문에서 예외 개체의 이름을 제공해야 합니다.  
  
 **오류 ID:** BC30666  
  
## <a name="to-correct-this-error"></a>이 오류를 해결하려면  
  
1. `System.Exception`에서 파생된 예외 개체의 이름을 지정합니다.  
  
2. `Throw` 문이 `Catch` 블록 내부에 있도록 코드를 재구성합니다.  
  
## <a name="see-also"></a>참조

- [Throw 문](../language-reference/statements/throw-statement.md)
- [Try...Catch...Finally 명령문](../language-reference/statements/try-catch-finally-statement.md)
- <xref:System.Exception?displayProperty=nameWithType>
- [.NET의 예외 처리 및 Throw](../../standard/exceptions/index.md)
